Workbook
Name LAD: 'Calcolo Master'!$AG:$AG
Name lstTipoValutazione: tblValutazioni[TipoValutazione]
Name lstTipoValutazione: tblValutazioni[TipoValutazione]
Name lstTipoValutazione: tblValutazioni[TipoValutazione]
Name ScenaAttiva: CONTROLLO!$B$9
Name SquadraAttiva: CONTROLLO!$B$8
Name StampaSchedeVuote: CONTROLLO!#REF!
Name TitoloScenaAttivo: CONTROLLO!$B$10

Sheet CONTROLLO
A1: SCENA | B1: SquadraCorrente | C1: TITOLO SCENA | D1: TimeStamp
A2: A | B2: 3 | C2: Una Scuola Stupefacente
A8: Squadra Attiva | B8: =INDEX(tblValutazioneAttiva[[#All],[SquadraCorrente]],2) -> 3
A9: Scena Attiva | B9: =INDEX(tblValutazioneAttiva[[#All],[SCENA]],2) -> A
A10: Titolo Scena Attivo | B10: =INDEX(tblValutazioneAttiva[[#All],[TITOLO SCENA]],2) -> Una Scuola Stupefacente
A11: GaraCodice | B11: GPSER-2026
A12: Chiave | B12: Valore
A13: StampaVuota | B13: SI
A20: ScenaCodice | B20: SlotScheda | C20: TipoScheda | D20: TotItem | E20: MaxSchede | F20: MaxSep | I20: ScenaCodice | J20: MaxTotScena | K20: MaxToSep | L20: NumeroSchede
A21: =INDEX(tblValutazioneAttiva[[#All],[SCENA]],2) -> A | B21: =_xlfn.XLOOKUP(tblScenaExportScheda[[#This Row],[TipoScheda]],MAP_SCENA!B:B,MAP_SCENA!A:A) -> 0 | C21: Master | D21: =COUNTIF(tblItems[TipoScheda], tblScenaExportScheda[[#This Row],[TipoScheda]]) -> 32 | E21: =SUMIFS(tblItems[TipoValutazione], tblItems[TipoScheda], tblScenaExportScheda[[#This Row],[TipoScheda]]) -> 0 | F21: =SUMIFS(tblItems[TipoValutazione], tblItems[TipoScheda], tblScenaExportScheda[[#This Row],[TipoScheda]], tblItems[PesoMax], TRUE) -> 0
A22: =INDEX(tblValutazioneAttiva[[#All],[SCENA]],2) -> A | B22: =_xlfn.XLOOKUP(tblScenaExportScheda[[#This Row],[TipoScheda]],MAP_SCENA!B:B,MAP_SCENA!A:A) -> 1 | C22: PBLS | D22: =COUNTIF(tblItems[TipoScheda], tblScenaExportScheda[[#This Row],[TipoScheda]]) -> 25 | E22: =SUMIFS(tblItems[TipoValutazione], tblItems[TipoScheda], tblScenaExportScheda[[#This Row],[TipoScheda]]) -> 0 | F22: =SUMIFS(tblItems[TipoValutazione], tblItems[TipoScheda], tblScenaExportScheda[[#This Row],[TipoScheda]], tblItems[PesoMax], TRUE) -> 0
A23: =INDEX(tblValutazioneAttiva[[#All],[SCENA]],2) -> A | B23: =_xlfn.XLOOKUP(tblScenaExportScheda[[#This Row],[TipoScheda]],MAP_SCENA!B:B,MAP_SCENA!A:A) -> 2 | C23: Overdose | D23: =COUNTIF(tblItems[TipoScheda], tblScenaExportScheda[[#This Row],[TipoScheda]]) -> 24 | E23: =SUMIFS(tblItems[TipoValutazione], tblItems[TipoScheda], tblScenaExportScheda[[#This Row],[TipoScheda]]) -> 0 | F23: =SUMIFS(tblItems[TipoValutazione], tblItems[TipoScheda], tblScenaExportScheda[[#This Row],[TipoScheda]], tblItems[PesoMax], TRUE) -> 0
A24: =INDEX(tblValutazioneAttiva[[#All],[SCENA]],2) -> A | B24: =_xlfn.XLOOKUP(tblScenaExportScheda[[#This Row],[TipoScheda]],MAP_SCENA!B:B,MAP_SCENA!A:A) -> 3 | C24: TC | D24: =COUNTIF(tblItems[TipoScheda], tblScenaExportScheda[[#This Row],[TipoScheda]]) -> 26 | E24: =SUMIFS(tblItems[TipoValutazione], tblItems[TipoScheda], tblScenaExportScheda[[#This Row],[TipoScheda]]) -> 0 | F24: =SUMIFS(tblItems[TipoValutazione], tblItems[TipoScheda], tblScenaExportScheda[[#This Row],[TipoScheda]], tblItems[PesoMax], TRUE) -> 0
A25: =INDEX(tblValutazioneAttiva[[#All],[SCENA]],2) -> A | B25: =_xlfn.XLOOKUP(tblScenaExportScheda[[#This Row],[TipoScheda]],MAP_SCENA!B:B,MAP_SCENA!A:A) -> 4 | C25: Asma | D25: =COUNTIF(tblItems[TipoScheda], tblScenaExportScheda[[#This Row],[TipoScheda]]) -> 24 | E25: =SUMIFS(tblItems[TipoValutazione], tblItems[TipoScheda], tblScenaExportScheda[[#This Row],[TipoScheda]]) -> 0 | F25: =SUMIFS(tblItems[TipoValutazione], tblItems[TipoScheda], tblScenaExportScheda[[#This Row],[TipoScheda]], tblItems[PesoMax], TRUE) -> 0

Sheet Valutazioni
A1: TipoValutazione | B1: MB | C1: BE | D1: SU | E1: IN | F1: NE
A2: Standard | B2: 5 | C2: 4 | D2: 2 | E2: 1 | F2: 0
A3: 3 Voci | B3: 3 | D3: 1 | F3: 0
A4: PesoDoppio | B4: 10 | C4: 8 | D4: 4 | E4: 1 | F4: 0
A5: Binario Punitivo | B5: 0 | F5: -50

Sheet APP_ITEMS
A1: TipoScheda | B1: Ordine | C1: ItemKey | D1: Sezione | E1: TestoItem | F1: TipoValutazione | G1: PesoMax | H1: IsSEP | I1: Has_MB | J1: Has_B | K1: Has_S | L1: Has_I | M1: Has_NE | N1: ScenaCodice | O1: IsBLS | P1: GaraCodice | Q1: SlotScheda
A2: Master | B2: 1 | C2: HDR_Master_AUTOPROTEZIONE_e_SICUREZZA | D2: AUTOPROTEZIONE e SICUREZZA | E2: AUTOPROTEZIONE e SICUREZZA | F2: HDR | G2: 0 | H2: FALSE | I2: FALSE | J2: FALSE | K2: FALSE | L2: FALSE | M2: FALSE | N2: A | O2: FALSE | P2: GPSER-2026 | Q2: 0
A3: Master | B3: 2 | C3: A_MAS0001 | D3: AUTOPROTEZIONE e SICUREZZA | E3: si guarda attorno (prima di entrare in scena) | F3: Standard | G3: 5 | H3: FALSE | I3: TRUE | J3: TRUE | K3: TRUE | L3: TRUE | M3: TRUE | N3: A | O3: FALSE | P3: GPSER-2026 | Q3: 0
A4: Master | B4: 3 | C4: A_MAS0002 | D4: AUTOPROTEZIONE e SICUREZZA | E4: indossa i d.p.i. in scena | F4: 3 Voci | G4: 3 | H4: FALSE | I4: TRUE | J4: FALSE | K4: TRUE | L4: FALSE | M4: TRUE | N4: A | O4: FALSE | P4: GPSER-2026 | Q4: 0
A5: Master | B5: 4 | C5: A_MAS0003 | D5: AUTOPROTEZIONE e SICUREZZA | E5: percorre tutta la scena e la rende sicura | F5: Standard | G5: 5 | H5: FALSE | I5: TRUE | J5: TRUE | K5: TRUE | L5: TRUE | M5: TRUE | N5: A | O5: FALSE | P5: GPSER-2026 | Q5: 0
A6: Master | B6: 5 | C6: HDR_Master_COMPORTAMENTO_CON_I_PRESENTI | D6: COMPORTAMENTO CON I PRESENTI | E6: COMPORTAMENTO CON I PRESENTI | F6: HDR | G6: 0 | H6: FALSE | I6: FALSE | J6: FALSE | K6: FALSE | L6: FALSE | M6: FALSE | N6: A | O6: FALSE | P6: GPSER-2026 | Q6: 0
A7: Master | B7: 6 | C7: A_MAS0004 | D7: COMPORTAMENTO CON I PRESENTI | E7: si presenta come soccorritore | F7: 3 Voci | G7: 3 | H7: FALSE | I7: TRUE | J7: FALSE | K7: TRUE | L7: FALSE | M7: TRUE | N7: A | O7: FALSE | P7: GPSER-2026 | Q7: 0
A8: Master | B8: 7 | C8: A_MAS0005 | D8: COMPORTAMENTO CON I PRESENTI | E8: indirizza con oculatezza i soccorritori | F8: Standard | G8: 5 | H8: FALSE | I8: TRUE | J8: TRUE | K8: TRUE | L8: TRUE | M8: TRUE | N8: A | O8: FALSE | P8: GPSER-2026 | Q8: 0
A9: Master | B9: 8 | C9: A_MAS0006 | D9: COMPORTAMENTO CON I PRESENTI | E9: atteggiamento cortese e determinato | F9: Standard | G9: 5 | H9: FALSE | I9: TRUE | J9: TRUE | K9: TRUE | L9: TRUE | M9: TRUE | N9: A | O9: FALSE | P9: GPSER-2026 | Q9: 0
A10: Master | B10: 9 | C10: HDR_Master_CHIAMATA_DI_SOCCORSO | D10: CHIAMATA DI SOCCORSO | E10: CHIAMATA DI SOCCORSO | F10: HDR | G10: 0 | H10: FALSE | I10: FALSE | J10: FALSE | K10: FALSE | L10: FALSE | M10: FALSE | N10: A | O10: FALSE | P10: GPSER-2026 | Q10: 0
A11: Master | B11: 10 | C11: A_MAS0007 | D11: CHIAMATA DI SOCCORSO | E11: fa la prima chiamata entro 2 minuti | F11: 3 Voci | G11: 3 | H11: FALSE | I11: TRUE | J11: FALSE | K11: TRUE | L11: FALSE | M11: TRUE | N11: A | O11: FALSE | P11: GPSER-2026 | Q11: 0
A12: Master | B12: 11 | C12: A_MAS0008 | D12: CHIAMATA DI SOCCORSO | E12: si identifica /presenta | F12: Standard | G12: 5 | H12: FALSE | I12: TRUE | J12: TRUE | K12: TRUE | L12: TRUE | M12: TRUE | N12: A | O12: FALSE | P12: GPSER-2026 | Q12: 0
A13: Master | B13: 12 | C13: A_MAS0009 | D13: CHIAMATA DI SOCCORSO | E13: spiega da dove chiama e indica come raggiungere il luogo | F13: 3 Voci | G13: 3 | H13: FALSE | I13: TRUE | J13: FALSE | K13: TRUE | L13: FALSE | M13: TRUE | N13: A | O13: FALSE | P13: GPSER-2026 | Q13: 0
... A132: Asma | B132: 24 | C132: A_ASM0021 | D132: ATTEGGIAMENTO DEL SOCCORRITORE | E132: valutazione del simulatore (ti sei sentito a tuo agio?) | F132: PesoDoppio | G132: 10 | H132: TRUE | I132: TRUE | J132: TRUE | K132: TRUE | L132: TRUE | M132: TRUE | N132: A | O132: FALSE | P132: GPSER-2026 | Q132: 4

Sheet APP_DATA
A1: ItemKey | B1: idValutazione | C1: Squadra | D1: Valore | E1: Timestamp | F1: Giudice | G1: TipoScheda | H1: ISSep | I1: SlotScheda | J1: __PowerAppsId__
A2: A_MAS0001 | B2: 1-A_MAS0001 | C2: 1 | D2: 4 | E2: 46130.609 | F2: Peter Griffin | G2: Master | H2: TRUE | I2: 0
A3: A_MAS0003 | B3: 1-A_MAS0003 | C3: 1 | D3: 4 | E3: 46130.609 | F3: Peter Griffin | G3: Master | H3: TRUE | I3: 0
A4: A_MAS0005 | B4: 1-A_MAS0005 | C4: 1 | D4: 4 | E4: 46130.609 | F4: Peter Griffin | G4: Master | H4: TRUE | I4: 0
A5: A_MAS0006 | B5: 1-A_MAS0006 | C5: 1 | D5: 4 | E5: 46130.609 | F5: Peter Griffin | G5: Master | H5: TRUE | I5: 0
A6: A_MAS0007 | B6: 1-A_MAS0007 | C6: 1 | D6: 3 | E6: 46130.609 | F6: Peter Griffin | G6: Master | H6: TRUE | I6: 0
A7: A_MAS0008 | B7: 1-A_MAS0008 | C7: 1 | D7: 5 | E7: 46130.609 | F7: Peter Griffin | G7: Master | H7: TRUE | I7: 0
A8: A_MAS0009 | B8: 1-A_MAS0009 | C8: 1 | D8: 1 | E8: 46130.609 | F8: Peter Griffin | G8: Master | H8: TRUE | I8: 0
A9: A_MAS0010 | B9: 1-A_MAS0010 | C9: 1 | D9: 4 | E9: 46130.609 | F9: Peter Griffin | G9: Master | H9: TRUE | I9: 0
A10: A_MAS0011 | B10: 1-A_MAS0011 | C10: 1 | D10: 3 | E10: 46130.609 | F10: Peter Griffin | G10: Master | H10: TRUE | I10: 0
A11: A_MAS0012 | B11: 1-A_MAS0012 | C11: 1 | D11: 3 | E11: 46130.609 | F11: Peter Griffin | G11: Master | H11: TRUE | I11: 0
A12: A_MAS0013 | B12: 1-A_MAS0013 | C12: 1 | D12: 3 | E12: 46130.609 | F12: Peter Griffin | G12: Master | H12: TRUE | I12: 0
A13: A_MAS0014 | B13: 1-A_MAS0014 | C13: 1 | D13: 3 | E13: 46130.609 | F13: Peter Griffin | G13: Master | H13: TRUE | I13: 0
... A343: A_OVE0021 | B343: 2-A_OVE0021 | C343: 2 | D343: 4 | E343: 46130.725 | F343: Homer Simpson | G343: Overdose | H343: TRUE | I343: 2

Sheet STAMPA_SCENA
A1: SquadraID | B1: Squadra_Nome
A2: 0 | B2: Prova
A3: 1 | B3: Carpineti
A4: 2 | B4: Scandiano
A5: 3 | B5: Liguria 1
A6: 4 | B6: Liguria 2
A7: 5 | B7: Liguria 3

Sheet MAP_SCENA
A1: A(SlotScheda) | B1: B (TipoScheda) | C1: SIGLA | D1: CodiceColonna | E1: IsBLS
A2: 0 | B2: Master | C2: MAS | D2: S0 | E2: NO
A3: 1 | B3: PBLS | C3: PBL | D3: S1 | E3: SI
A4: 2 | B4: Overdose | C4: OVE | D4: S2 | E4: NO
A5: 3 | B5: TC | C5: TCR | D5: S3 | E5: NO
A6: 4 | B6: Asma | C6: ASM | D6: S4 | E6: NO

Sheet CLASSIFICA
A1: SquadraID | B1: Squadra_Nome | C1: S0 | D1: S1 | E1: S2 | F1: S3 | G1: S4 | H1: S5 | I1: S6 | J1: Totale | K1: SEP | L1: RankTOT | M1: RankSEP | N1: MaxTotScena | O1: Percentuale | P1: MaxToSep | Q1: PercentualeSEP
A2: 1 | B2: Carpineti | C2: =SUMIFS(APP_DATA!$D:$D,APP_DATA!$C:$C,tblClassificaNorm[[#This Row],[SquadraID]],APP_DATA!$I:$I,0) -> 98 | D2: =SUMIFS(APP_DATA!$D:$D,APP_DATA!$C:$C,tblClassificaNorm[[#This Row],[SquadraID]],APP_DATA!$I:$I,1) -> 80 | E2: =SUMIFS(APP_DATA!$D:$D,APP_DATA!$C:$C,tblClassificaNorm[[#This Row],[SquadraID]],APP_DATA!$I:$I,2) -> 43 | F2: =SUMIFS(APP_DATA!$D:$D,APP_DATA!$C:$C,tblClassificaNorm[[#This Row],[SquadraID]],APP_DATA!$I:$I,3) -> 55 | G2: =SUMIFS(APP_DATA!$D:$D,APP_DATA!$C:$C,tblClassificaNorm[[#This Row],[SquadraID]],APP_DATA!$I:$I,4) -> 83 | H2: =SUMIFS(APP_DATA!$D:$D,APP_DATA!$C:$C,tblClassificaNorm[[#This Row],[SquadraID]],APP_DATA!$I:$I,5) -> 0 | I2: =SUMIFS(APP_DATA!$D:$D,APP_DATA!$C:$C,tblClassificaNorm[[#This Row],[SquadraID]],APP_DATA!$I:$I,6) -> 0 | J2: =SUMIF(APP_DATA!$C:$C,tblClassificaNorm[[#This Row],[SquadraID]],APP_DATA!$D:$D) -> 359 | K2: =SUMIFS(APP_DATA!$D:$D,APP_DATA!$C:$C,tblClassificaNorm[[#This Row],[SquadraID]],APP_DATA!$H:$H,TRUE) -> 154 | L2: =_xlfn.RANK.EQ(tblClassificaNorm[[#This Row],[Totale]],tblClassificaNorm[Totale],0) -> 2 | M2: =_xlfn.RANK.EQ(tblClassificaNorm[[#This Row],[SEP]],tblClassificaNorm[SEP],0) -> 1 | N2: =SUM(tblScenaExportScheda[MaxSchede]) -> 0 | O2: =IF(tblClassificaNorm[[#This Row],[MaxTotScena]]=0, 0, tblClassificaNorm[[#This Row],[Totale]]/tblClassificaNorm[[#This Row],[MaxTotScena]]) -> 0 | P2: =SUM(tblScenaExportScheda[MaxSep]) -> 0
A3: 2 | B3: Scandiano | C3: =SUMIFS(APP_DATA!$D:$D,APP_DATA!$C:$C,tblClassificaNorm[[#This Row],[SquadraID]],APP_DATA!$I:$I,0) -> 109 | D3: =SUMIFS(APP_DATA!$D:$D,APP_DATA!$C:$C,tblClassificaNorm[[#This Row],[SquadraID]],APP_DATA!$I:$I,1) -> 81 | E3: =SUMIFS(APP_DATA!$D:$D,APP_DATA!$C:$C,tblClassificaNorm[[#This Row],[SquadraID]],APP_DATA!$I:$I,2) -> 48 | F3: =SUMIFS(APP_DATA!$D:$D,APP_DATA!$C:$C,tblClassificaNorm[[#This Row],[SquadraID]],APP_DATA!$I:$I,3) -> 71 | G3: =SUMIFS(APP_DATA!$D:$D,APP_DATA!$C:$C,tblClassificaNorm[[#This Row],[SquadraID]],APP_DATA!$I:$I,4) -> 77 | H3: =SUMIFS(APP_DATA!$D:$D,APP_DATA!$C:$C,tblClassificaNorm[[#This Row],[SquadraID]],APP_DATA!$I:$I,5) -> 0 | I3: =SUMIFS(APP_DATA!$D:$D,APP_DATA!$C:$C,tblClassificaNorm[[#This Row],[SquadraID]],APP_DATA!$I:$I,6) -> 0 | J3: =SUMIF(APP_DATA!$C:$C,tblClassificaNorm[[#This Row],[SquadraID]],APP_DATA!$D:$D) -> 386 | K3: =SUMIFS(APP_DATA!$D:$D,APP_DATA!$C:$C,tblClassificaNorm[[#This Row],[SquadraID]],APP_DATA!$H:$H,TRUE) -> 100 | L3: =_xlfn.RANK.EQ(tblClassificaNorm[[#This Row],[Totale]],tblClassificaNorm[Totale],0) -> 1 | M3: =_xlfn.RANK.EQ(tblClassificaNorm[[#This Row],[SEP]],tblClassificaNorm[SEP],0) -> 2 | N3: =SUM(tblScenaExportScheda[MaxSchede]) -> 0 | O3: =IF(tblClassificaNorm[[#This Row],[MaxTotScena]]=0, 0, tblClassificaNorm[[#This Row],[Totale]]/tblClassificaNorm[[#This Row],[MaxTotScena]]) -> 0 | P3: =SUM(tblScenaExportScheda[MaxSep]) -> 0
A4: 3 | B4: Liguria 1 | C4: =SUMIFS(APP_DATA!$D:$D,APP_DATA!$C:$C,tblClassificaNorm[[#This Row],[SquadraID]],APP_DATA!$I:$I,0) -> 60 | D4: =SUMIFS(APP_DATA!$D:$D,APP_DATA!$C:$C,tblClassificaNorm[[#This Row],[SquadraID]],APP_DATA!$I:$I,1) -> 39 | E4: =SUMIFS(APP_DATA!$D:$D,APP_DATA!$C:$C,tblClassificaNorm[[#This Row],[SquadraID]],APP_DATA!$I:$I,2) -> 44 | F4: =SUMIFS(APP_DATA!$D:$D,APP_DATA!$C:$C,tblClassificaNorm[[#This Row],[SquadraID]],APP_DATA!$I:$I,3) -> 47 | G4: =SUMIFS(APP_DATA!$D:$D,APP_DATA!$C:$C,tblClassificaNorm[[#This Row],[SquadraID]],APP_DATA!$I:$I,4) -> 1 | H4: =SUMIFS(APP_DATA!$D:$D,APP_DATA!$C:$C,tblClassificaNorm[[#This Row],[SquadraID]],APP_DATA!$I:$I,5) -> 0 | I4: =SUMIFS(APP_DATA!$D:$D,APP_DATA!$C:$C,tblClassificaNorm[[#This Row],[SquadraID]],APP_DATA!$I:$I,6) -> 0 | J4: =SUMIF(APP_DATA!$C:$C,tblClassificaNorm[[#This Row],[SquadraID]],APP_DATA!$D:$D) -> 191 | K4: =SUMIFS(APP_DATA!$D:$D,APP_DATA!$C:$C,tblClassificaNorm[[#This Row],[SquadraID]],APP_DATA!$H:$H,TRUE) -> 51 | L4: =_xlfn.RANK.EQ(tblClassificaNorm[[#This Row],[Totale]],tblClassificaNorm[Totale],0) -> 3 | M4: =_xlfn.RANK.EQ(tblClassificaNorm[[#This Row],[SEP]],tblClassificaNorm[SEP],0) -> 3 | N4: =SUM(tblScenaExportScheda[MaxSchede]) -> 0 | O4: =IF(tblClassificaNorm[[#This Row],[MaxTotScena]]=0, 0, tblClassificaNorm[[#This Row],[Totale]]/tblClassificaNorm[[#This Row],[MaxTotScena]]) -> 0 | P4: =SUM(tblScenaExportScheda[MaxSep]) -> 0
A5: 4 | B5: Liguria 2 | C5: =SUMIFS(APP_DATA!$D:$D,APP_DATA!$C:$C,tblClassificaNorm[[#This Row],[SquadraID]],APP_DATA!$I:$I,0) -> 0 | D5: =SUMIFS(APP_DATA!$D:$D,APP_DATA!$C:$C,tblClassificaNorm[[#This Row],[SquadraID]],APP_DATA!$I:$I,1) -> 0 | E5: =SUMIFS(APP_DATA!$D:$D,APP_DATA!$C:$C,tblClassificaNorm[[#This Row],[SquadraID]],APP_DATA!$I:$I,2) -> 0 | F5: =SUMIFS(APP_DATA!$D:$D,APP_DATA!$C:$C,tblClassificaNorm[[#This Row],[SquadraID]],APP_DATA!$I:$I,3) -> 0 | G5: =SUMIFS(APP_DATA!$D:$D,APP_DATA!$C:$C,tblClassificaNorm[[#This Row],[SquadraID]],APP_DATA!$I:$I,4) -> 0 | H5: =SUMIFS(APP_DATA!$D:$D,APP_DATA!$C:$C,tblClassificaNorm[[#This Row],[SquadraID]],APP_DATA!$I:$I,5) -> 0 | I5: =SUMIFS(APP_DATA!$D:$D,APP_DATA!$C:$C,tblClassificaNorm[[#This Row],[SquadraID]],APP_DATA!$I:$I,6) -> 0 | J5: =SUMIF(APP_DATA!$C:$C,tblClassificaNorm[[#This Row],[SquadraID]],APP_DATA!$D:$D) -> 0 | K5: =SUMIFS(APP_DATA!$D:$D,APP_DATA!$C:$C,tblClassificaNorm[[#This Row],[SquadraID]],APP_DATA!$H:$H,TRUE) -> 0 | L5: =_xlfn.RANK.EQ(tblClassificaNorm[[#This Row],[Totale]],tblClassificaNorm[Totale],0) -> 4 | M5: =_xlfn.RANK.EQ(tblClassificaNorm[[#This Row],[SEP]],tblClassificaNorm[SEP],0) -> 4 | N5: =SUM(tblScenaExportScheda[MaxSchede]) -> 0 | O5: =IF(tblClassificaNorm[[#This Row],[MaxTotScena]]=0, 0, tblClassificaNorm[[#This Row],[Totale]]/tblClassificaNorm[[#This Row],[MaxTotScena]]) -> 0 | P5: =SUM(tblScenaExportScheda[MaxSep]) -> 0
A6: 5 | B6: Liguria 3 | C6: =SUMIFS(APP_DATA!$D:$D,APP_DATA!$C:$C,tblClassificaNorm[[#This Row],[SquadraID]],APP_DATA!$I:$I,0) -> 0 | D6: =SUMIFS(APP_DATA!$D:$D,APP_DATA!$C:$C,tblClassificaNorm[[#This Row],[SquadraID]],APP_DATA!$I:$I,1) -> 0 | E6: =SUMIFS(APP_DATA!$D:$D,APP_DATA!$C:$C,tblClassificaNorm[[#This Row],[SquadraID]],APP_DATA!$I:$I,2) -> 0 | F6: =SUMIFS(APP_DATA!$D:$D,APP_DATA!$C:$C,tblClassificaNorm[[#This Row],[SquadraID]],APP_DATA!$I:$I,3) -> 0 | G6: =SUMIFS(APP_DATA!$D:$D,APP_DATA!$C:$C,tblClassificaNorm[[#This Row],[SquadraID]],APP_DATA!$I:$I,4) -> 0 | H6: =SUMIFS(APP_DATA!$D:$D,APP_DATA!$C:$C,tblClassificaNorm[[#This Row],[SquadraID]],APP_DATA!$I:$I,5) -> 0 | I6: =SUMIFS(APP_DATA!$D:$D,APP_DATA!$C:$C,tblClassificaNorm[[#This Row],[SquadraID]],APP_DATA!$I:$I,6) -> 0 | J6: =SUMIF(APP_DATA!$C:$C,tblClassificaNorm[[#This Row],[SquadraID]],APP_DATA!$D:$D) -> 0 | K6: =SUMIFS(APP_DATA!$D:$D,APP_DATA!$C:$C,tblClassificaNorm[[#This Row],[SquadraID]],APP_DATA!$H:$H,TRUE) -> 0 | L6: =_xlfn.RANK.EQ(tblClassificaNorm[[#This Row],[Totale]],tblClassificaNorm[Totale],0) -> 4 | M6: =_xlfn.RANK.EQ(tblClassificaNorm[[#This Row],[SEP]],tblClassificaNorm[SEP],0) -> 4 | N6: =SUM(tblScenaExportScheda[MaxSchede]) -> 0 | O6: =IF(tblClassificaNorm[[#This Row],[MaxTotScena]]=0, 0, tblClassificaNorm[[#This Row],[Totale]]/tblClassificaNorm[[#This Row],[MaxTotScena]]) -> 0 | P6: =SUM(tblScenaExportScheda[MaxSep]) -> 0

Sheet DATI_OLD
A1: SCENA | B1: SQUADRA | C1: TITOLO SCENA | H1: =INDEX(tblValutazioneAttiva[[#All],[SquadraCorrente]],2) -> 3 | I1: =INDEX(tblValutazioneAttiva[[#All],[SCENA]],2) -> A | J1: =INDEX(tblValutazioneAttiva[[#All],[TITOLO SCENA]],2) -> Una Scuola Stupefacente
A2: A | B2: {=SquadraAttiva} -> 3 | C2: {=TitoloScenaAttivo} -> Una Scuola Stupefacente
A7: SCHEDE
A9: RUOLO | B9: Simulatore | C9: Patologia | D9: Coscienza | E9: FR | F9: FC | G9: CUTE | H9: Codice Scheda | I9: Punteggio Massimo | J9: Realizzato | K9: Percentuale | L9: SEP | M9: Sep Realizzato | O9: Giudice
A10: Master | B10: M | C10: Master | H10: {=ScenaAttiva&TEXT(SquadraAttiva,"00")&TEXT(B10,"00")} -> A03M | I10: =SUM('Calcolo Master'!H2:H41) -> 120 | J10: ='Calcolo Master'!J43 -> 0 | K10: =J10/I10 -> 0 | L10: ='Calcolo Master'!AA14 -> 35 | M10: ='Calcolo Master'!J44 -> 0
A11: Giudice 1 | B11: 1 | C11: Emorragia femorale | D11: V | E11: 26 | F11: 140 | G11: Pallida, sudta | H11: {=ScenaAttiva&TEXT(SquadraAttiva,"00")&TEXT(B11,"00")} -> A0301 | I11: =SUM('Calcolo PBLS'!H2:H40) -> 109 | J11: ='Calcolo PBLS'!J42 -> 0 | K11: =J11/I11 -> 0 | L11: ='Calcolo PBLS'!AA14 -> 0 | M11: ='Calcolo PBLS'!J43 -> 0
A12: Giudice 2 | B12: 2 | C12: Trauma | D12: A | E12: 26 | F12: 110 | G12: Pallida, sudata | H12: {=ScenaAttiva&TEXT(SquadraAttiva,"00")&TEXT(B12,"00")} -> A0302 | I12: =SUM('Calcolo TC'!H2:H40) -> 106 | J12: ='Calcolo TC'!J42 -> 0 | K12: =J12/I12 -> 0 | L12: ='Calcolo TC'!AA14 -> 0 | M12: ='Calcolo TC'!J43 -> 0
A13: Giudice 3 | B13: 3 | C13: Frattura Polso | D13: A | E13: 22 | F13: 105 | G13: Normale | H13: {=ScenaAttiva&TEXT(SquadraAttiva,"00")&TEXT(B13,"00")} -> A0303 | I13: =SUM('Calcolo Overdose'!H2:H40) -> 105 | J13: ='Calcolo Overdose'!J42 -> 0 | K13: =J13/I13 -> 0 | L13: ='Calcolo Overdose'!AA14 -> 0 | M13: ='Calcolo Overdose'!J43 -> 0
A14: Giudice 4 | B14: 4 | C14: Sincope | D14: A | E14: 20 | F14: 90 | G14: Pallida, sudata | H14: {=ScenaAttiva&TEXT(SquadraAttiva,"00")&TEXT(B14,"00")} -> A0304 | I14: =SUM('Calcolo Asma'!H2:H40) -> 98 | J14: ='Calcolo Asma'!J42 -> 0 | K14: =J14/I14 -> 0 | L14: ='Calcolo Asma'!AA14 -> 0 | M14: ='Calcolo Asma'!J43 -> 0
I18: Punteggio Massimo scena | J18: Punteggio realizzato | K18: Percentuale
I19: =SUM(I10:I14) -> 538 | J19: =SUM(J10:J14) -> 0 | K19: =J19/I19 -> 0
I21: SEP Massimo | J21: Sep Realizzato | K21: Percentuale
I22: =SUM(L10:L14) -> 35 | J22: =SUM(M10:M14) -> 0 | K22: =J22/I22 -> 0
I24: BLSD Massimo | J24: BLSD Realizzato | K24: Percentuale
I25: 0 | J25: 0 | K25: =IF(I25=0,0,J25/I25) -> 0
I27: Leader Massimo | J27: Leader Realizzato | K27: Percentuale
I28: ='Calcolo Master'!AA11 -> 120 | J28: ='Calcolo Master'!J43 -> 0 | K28: =tblLeader19[[#This Row],[Leader Realizzato]]/tblLeader19[[#This Row],[Leader Massimo]] -> 0

Sheet DATI
A1: ScenaCodice | B1: TitoloScena | C1: TimeStampScena | D1: StatoScena | N1: ScenaCodice_tmp | O1: SquadraID_tmp
N2: =CONTROLLO!B1 -> SquadraCorrente
A5: Ruolo | B5: SimulatoreCodice | C5: Patologia | D5: FR | E5: FC | F5: Coscienza | G5: Cute | H5: Giudice | I5: Attiva
A6: Master | B6: M | C6: Master | I6: TRUE
A7: Giudice 1 | B7: 1 | C7: PBLS | F7: U | I7: TRUE
A8: Giudice 2 | B8: 2 | C8: Overdose | D8: 10 | E8: 60 | F8: P | G8: Pallida, sudata | I8: TRUE
A9: Giudice 3 | B9: 3 | C9: TC | D9: 26 | E9: 124 | F9: V | G9: Pallida, sudata | I9: TRUE
A10: Giudice 4 | B10: 4 | C10: Asma | D10: 28 | E10: 110 | F10: A | G10: Pallida, sudata | I10: TRUE
A11: Giudice 5 | B11: 5 | C11: Agitata | F11: A | I11: TRUE

Sheet Calcolo Master
B1: ValoreSquadra_Helper | C1: IdValutazione_Helper | D1: ValoreHelper | E1: SEP | G1: Tipo Valutazione | H1: Molto bene | K1: Bene | N1: Soddisfacente | Q1: Insufficiente | T1: Non fatto | Y1: SEP | AG1: LAD
A2: =IF(G2<>"",ScenaAttiva&"_"&AB$4&TEXT(COUNTIF($G2:G$3,"<>"),"0000"),"") | B2: =IF(A2<>"",SquadraAttiva,"") | C2: =IF(A2<>"",TEXT(B2,"0")&"-"&TRIM(A2),"") | D2: =IFERROR(_xlfn.XLOOKUP(C2,tblRisposte[idValutazione],tblRisposte[Valore],""),"") | F2: AUTOPROTEZIONE e SICUREZZA | Z2: Scena | AA2: {=ScenaAttiva} -> A | AB2: Squadra | AC2: {=SquadraAttiva} -> 3 | AD2: Simulatore | AE2: M
A3: =IF(G3<>"",ScenaAttiva&"_"&AB$4&TEXT(COUNTIF($G3:G$3,"<>"),"0000"),"") -> A_MAS0001 | B3: =IF(A3<>"",SquadraAttiva,"") -> 3 | C3: =IF(A3<>"",TEXT(B3,"0")&"-"&TRIM(A3),"") -> 3-A_MAS0001 | D3: =IFERROR(_xlfn.XLOOKUP(C3,tblRisposte[idValutazione],tblRisposte[Valore],""),"") -> 1 | F3: si guarda attorno (prima di entrare in scena) | G3: Standard | H3: {=_xlfn.LET(_xlpm.v,_xlfn.XLOOKUP(G3,tblValutazioni[TipoValutazione],tblValutazioni[MB],""),IF(_xlpm.v="","",_xlpm.v))} -> 5 | I3: =IF(_xlfn.XLOOKUP($A3, tblRisposte[ItemKey],tblRisposte[Valore],"")="Molto bene","X",0) -> 0 | J3: =IF((I3="X"),H3,0) -> 0 | K3: {=_xlfn.LET(_xlpm.v,_xlfn.XLOOKUP(G3,tblValutazioni[TipoValutazione],tblValutazioni[BE],""),IF(_xlpm.v="","",_xlpm.v))} -> 4 | L3: =IF(_xlfn.XLOOKUP($A3, tblRisposte[ItemKey], tblRisposte[Valore], "")="Bene", "X", 0) -> 0 | M3: =IF((L3="X"),K3,0) -> 0 | N3: {=_xlfn.LET(_xlpm.v,_xlfn.XLOOKUP(G3,tblValutazioni[TipoValutazione],tblValutazioni[SU],""),IF(_xlpm.v="","",_xlpm.v))} -> 2 | O3: =IF(_xlfn.XLOOKUP($A3, tblRisposte[ItemKey], tblRisposte[Valore], "")="Soddisfacente","X",0) -> 0 | P3: =IF((O3="X"),N3,0) -> 0 | Q3: {=_xlfn.LET(_xlpm.v,_xlfn.XLOOKUP(G3,tblValutazioni[TipoValutazione],tblValutazioni[IN],""),IF(_xlpm.v="","",_xlpm.v))} -> 1 | R3: =IF(_xlfn.XLOOKUP($A3, tblRisposte[ItemKey], tblRisposte[Valore], "")="Insufficiente","X",0) -> 0 | S3: =IF((R3="X"),Q3,0) -> 0 | T3: {=_xlfn.LET(_xlpm.v,_xlfn.XLOOKUP(G3,tblValutazioni[TipoValutazione],tblValutazioni[NE],""),IF(_xlpm.v="","",_xlpm.v))} -> 0 | U3: =IF(_xlfn.XLOOKUP($A3, tblRisposte[ItemKey], tblRisposte[Valore], "")="Non eseguito","X",0) -> 0 | V3: =IF((U3="X"),T3,0) -> 0 | W3: =COUNTIF(I3,"x")+COUNTIF(L3,"x")+COUNTIF(O3,"x")+COUNTIF(R3,"x")+COUNTIF(U3,"x") -> 0 | X3: =IF(COUNTIF(I3:U3,"X")=1,"OK","errore") -> errore | Y3: =IF(E3="SEP",IF(I3="x",H3,IF(L3="X",K3,IF(O3="x",N3,IF(R3="X",Q3,IF(U3="X",T3,""))))),"") | AG3: 5
A4: =IF(G4<>"",ScenaAttiva&"_"&AB$4&TEXT(COUNTIF($G$3:G4,"<>"),"0000"),"") -> A_MAS0002 | B4: =IF(A4<>"",SquadraAttiva,"") -> 3 | C4: =IF(A4<>"",TEXT(B4,"0")&"-"&TRIM(A4),"") -> 3-A_MAS0002 | D4: =IFERROR(_xlfn.XLOOKUP(C4,tblRisposte[idValutazione],tblRisposte[Valore],""),"") -> 3 | F4: indossa i d.p.i. in scena | G4: 3 Voci | H4: {=_xlfn.LET(_xlpm.v,_xlfn.XLOOKUP(G4,tblValutazioni[TipoValutazione],tblValutazioni[MB],""),IF(_xlpm.v="","",_xlpm.v))} -> 3 | I4: =IF(_xlfn.XLOOKUP($A4, tblRisposte[ItemKey],tblRisposte[Valore],"")="Molto bene","X",0) -> 0 | J4: =IF((I4="X"),H4,0) -> 0 | K4: {=_xlfn.LET(_xlpm.v,_xlfn.XLOOKUP(G4,tblValutazioni[TipoValutazione],tblValutazioni[BE],""),IF(_xlpm.v="","",_xlpm.v))} | L4: =IF(_xlfn.XLOOKUP($A4, tblRisposte[ItemKey], tblRisposte[Valore], "")="Bene", "X", 0) -> 0 | M4: =IF((L4="X"),K4,0) -> 0 | N4: {=_xlfn.LET(_xlpm.v,_xlfn.XLOOKUP(G4,tblValutazioni[TipoValutazione],tblValutazioni[SU],""),IF(_xlpm.v="","",_xlpm.v))} -> 1 | O4: =IF(_xlfn.XLOOKUP($A4, tblRisposte[ItemKey], tblRisposte[Valore], "")="Soddisfacente","X",0) -> 0 | P4: =IF((O4="X"),N4,0) -> 0 | Q4: {=_xlfn.LET(_xlpm.v,_xlfn.XLOOKUP(G4,tblValutazioni[TipoValutazione],tblValutazioni[IN],""),IF(_xlpm.v="","",_xlpm.v))} | R4: =IF(_xlfn.XLOOKUP($A4, tblRisposte[ItemKey], tblRisposte[Valore], "")="Insufficiente","X",0) -> 0 | S4: =IF((R4="X"),Q4,0) -> 0 | T4: {=_xlfn.LET(_xlpm.v,_xlfn.XLOOKUP(G4,tblValutazioni[TipoValutazione],tblValutazioni[NE],""),IF(_xlpm.v="","",_xlpm.v))} -> 0 | U4: =IF(_xlfn.XLOOKUP($A4, tblRisposte[ItemKey], tblRisposte[Valore], "")="Non eseguito","X",0) -> 0 | V4: =IF((U4="X"),T4,0) -> 0 | W4: =COUNTIF(I4,"x")+COUNTIF(L4,"x")+COUNTIF(O4,"x")+COUNTIF(R4,"x")+COUNTIF(U4,"x") -> 0 | X4: =IF(COUNTIF(I4:U4,"X")=1,"OK","errore") -> errore | Y4: =IF(E4="SEP",IF(I4="x",H4,IF(L4="X",K4,IF(O4="x",N4,IF(R4="X",Q4,IF(U4="X",T4,""))))),"") | Z4: Patologia | AA4: 0 | AB4: {=INDEX(tblMapSchede[[#All],[SIGLA]],AA$4+2)} -> MAS
A5: =IF(G5<>"",ScenaAttiva&"_"&AB$4&TEXT(COUNTIF($G$3:G5,"<>"),"0000"),"") -> A_MAS0003 | B5: =IF(A5<>"",SquadraAttiva,"") -> 3 | C5: =IF(A5<>"",TEXT(B5,"0")&"-"&TRIM(A5),"") -> 3-A_MAS0003 | D5: =IFERROR(_xlfn.XLOOKUP(C5,tblRisposte[idValutazione],tblRisposte[Valore],""),"") -> 1 | F5: percorre tutta la scena e la rende sicura | G5: Standard | H5: {=_xlfn.LET(_xlpm.v,_xlfn.XLOOKUP(G5,tblValutazioni[TipoValutazione],tblValutazioni[MB],""),IF(_xlpm.v="","",_xlpm.v))} -> 5 | I5: =IF(_xlfn.XLOOKUP($A5, tblRisposte[ItemKey],tblRisposte[Valore],"")="Molto bene","X",0) -> 0 | J5: =IF((I5="X"),H5,0) -> 0 | K5: {=_xlfn.LET(_xlpm.v,_xlfn.XLOOKUP(G5,tblValutazioni[TipoValutazione],tblValutazioni[BE],""),IF(_xlpm.v="","",_xlpm.v))} -> 4 | L5: =IF(_xlfn.XLOOKUP($A5, tblRisposte[ItemKey], tblRisposte[Valore], "")="Bene", "X", 0) -> 0 | M5: =IF((L5="X"),K5,0) -> 0 | N5: {=_xlfn.LET(_xlpm.v,_xlfn.XLOOKUP(G5,tblValutazioni[TipoValutazione],tblValutazioni[SU],""),IF(_xlpm.v="","",_xlpm.v))} -> 2 | O5: =IF(_xlfn.XLOOKUP($A5, tblRisposte[ItemKey], tblRisposte[Valore], "")="Soddisfacente","X",0) -> 0 | P5: =IF((O5="X"),N5,0) -> 0 | Q5: {=_xlfn.LET(_xlpm.v,_xlfn.XLOOKUP(G5,tblValutazioni[TipoValutazione],tblValutazioni[IN],""),IF(_xlpm.v="","",_xlpm.v))} -> 1 | R5: =IF(_xlfn.XLOOKUP($A5, tblRisposte[ItemKey], tblRisposte[Valore], "")="Insufficiente","X",0) -> 0 | S5: =IF((R5="X"),Q5,0) -> 0 | T5: {=_xlfn.LET(_xlpm.v,_xlfn.XLOOKUP(G5,tblValutazioni[TipoValutazione],tblValutazioni[NE],""),IF(_xlpm.v="","",_xlpm.v))} -> 0 | U5: =IF(_xlfn.XLOOKUP($A5, tblRisposte[ItemKey], tblRisposte[Valore], "")="Non eseguito","X",0) -> 0 | V5: =IF((U5="X"),T5,0) -> 0 | W5: =COUNTIF(I5,"x")+COUNTIF(L5,"x")+COUNTIF(O5,"x")+COUNTIF(R5,"x")+COUNTIF(U5,"x") -> 0 | X5: =IF(COUNTIF(I5:U5,"X")=1,"OK","errore") -> errore | Y5: =IF(E5="SEP",IF(I5="x",H5,IF(L5="X",K5,IF(O5="x",N5,IF(R5="X",Q5,IF(U5="X",T5,""))))),"")
A6: =IF(G6<>"",ScenaAttiva&"_"&AB$4&TEXT(COUNTIF($G$3:G6,"<>"),"0000"),"") | B6: =IF(A6<>"",SquadraAttiva,"") | C6: =IF(A6<>"",TEXT(B6,"0")&"-"&TRIM(A6),"") | D6: =IFERROR(_xlfn.XLOOKUP(C6,tblRisposte[idValutazione],tblRisposte[Valore],""),"") | F6: COMPORTAMENTO CON I PRESENTI | H6: {=_xlfn.LET(_xlpm.v,_xlfn.XLOOKUP(G6,tblValutazioni[TipoValutazione],tblValutazioni[MB],""),IF(_xlpm.v="","",_xlpm.v))} | I6: =IF(_xlfn.XLOOKUP($A6, tblRisposte[ItemKey],tblRisposte[Valore],"")="Molto bene","X",0) -> 0 | J6: =IF((I6="X"),H6,0) -> 0 | K6: {=_xlfn.LET(_xlpm.v,_xlfn.XLOOKUP(G6,tblValutazioni[TipoValutazione],tblValutazioni[BE],""),IF(_xlpm.v="","",_xlpm.v))} | L6: =IF(_xlfn.XLOOKUP($A6, tblRisposte[ItemKey], tblRisposte[Valore], "")="Bene", "X", 0) -> 0 | M6: =IF((L6="X"),K6,0) -> 0 | N6: {=_xlfn.LET(_xlpm.v,_xlfn.XLOOKUP(G6,tblValutazioni[TipoValutazione],tblValutazioni[SU],""),IF(_xlpm.v="","",_xlpm.v))} | O6: =IF(_xlfn.XLOOKUP($A6, tblRisposte[ItemKey], tblRisposte[Valore], "")="Soddisfacente","X",0) -> 0 | P6: =IF((O6="X"),N6,0) -> 0 | Q6: {=_xlfn.LET(_xlpm.v,_xlfn.XLOOKUP(G6,tblValutazioni[TipoValutazione],tblValutazioni[IN],""),IF(_xlpm.v="","",_xlpm.v))} | R6: =IF(_xlfn.XLOOKUP($A6, tblRisposte[ItemKey], tblRisposte[Valore], "")="Insufficiente","X",0) -> 0 | S6: =IF((R6="X"),Q6,0) -> 0 | T6: {=_xlfn.LET(_xlpm.v,_xlfn.XLOOKUP(G6,tblValutazioni[TipoValutazione],tblValutazioni[NE],""),IF(_xlpm.v="","",_xlpm.v))} | U6: =IF(_xlfn.XLOOKUP($A6, tblRisposte[ItemKey], tblRisposte[Valore], "")="Non eseguito","X",0) -> 0 | V6: =IF((U6="X"),T6,0) -> 0 | W6: =COUNTIF(I6,"x")+COUNTIF(L6,"x")+COUNTIF(O6,"x")+COUNTIF(R6,"x")+COUNTIF(U6,"x") -> 0 | X6: =IF(COUNTIF(I6:U6,"X")=1,"OK","errore") -> errore | Y6: =IF(E6="SEP",IF(I6="x",H6,IF(L6="X",K6,IF(O6="x",N6,IF(R6="X",Q6,IF(U6="X",T6,""))))),"") | Z6: Sentiero della memoria
A7: =IF(G7<>"",ScenaAttiva&"_"&AB$4&TEXT(COUNTIF($G$3:G7,"<>"),"0000"),"") -> A_MAS0004 | B7: =IF(A7<>"",SquadraAttiva,"") -> 3 | C7: =IF(A7<>"",TEXT(B7,"0")&"-"&TRIM(A7),"") -> 3-A_MAS0004 | D7: =IFERROR(_xlfn.XLOOKUP(C7,tblRisposte[idValutazione],tblRisposte[Valore],""),"") -> 1 | F7: si presenta come soccorritore | G7: 3 Voci | H7: {=_xlfn.LET(_xlpm.v,_xlfn.XLOOKUP(G7,tblValutazioni[TipoValutazione],tblValutazioni[MB],""),IF(_xlpm.v="","",_xlpm.v))} -> 3 | I7: =IF(_xlfn.XLOOKUP($A7, tblRisposte[ItemKey],tblRisposte[Valore],"")="Molto bene","X",0) -> 0 | J7: =IF((I7="X"),H7,0) -> 0 | K7: {=_xlfn.LET(_xlpm.v,_xlfn.XLOOKUP(G7,tblValutazioni[TipoValutazione],tblValutazioni[BE],""),IF(_xlpm.v="","",_xlpm.v))} | L7: =IF(_xlfn.XLOOKUP($A7, tblRisposte[ItemKey], tblRisposte[Valore], "")="Bene", "X", 0) -> 0 | M7: =IF((L7="X"),K7,0) -> 0 | N7: {=_xlfn.LET(_xlpm.v,_xlfn.XLOOKUP(G7,tblValutazioni[TipoValutazione],tblValutazioni[SU],""),IF(_xlpm.v="","",_xlpm.v))} -> 1 | O7: =IF(_xlfn.XLOOKUP($A7, tblRisposte[ItemKey], tblRisposte[Valore], "")="Soddisfacente","X",0) -> 0 | P7: =IF((O7="X"),N7,0) -> 0 | Q7: {=_xlfn.LET(_xlpm.v,_xlfn.XLOOKUP(G7,tblValutazioni[TipoValutazione],tblValutazioni[IN],""),IF(_xlpm.v="","",_xlpm.v))} | R7: =IF(_xlfn.XLOOKUP($A7, tblRisposte[ItemKey], tblRisposte[Valore], "")="Insufficiente","X",0) -> 0 | S7: =IF((R7="X"),Q7,0) -> 0 | T7: {=_xlfn.LET(_xlpm.v,_xlfn.XLOOKUP(G7,tblValutazioni[TipoValutazione],tblValutazioni[NE],""),IF(_xlpm.v="","",_xlpm.v))} -> 0 | U7: =IF(_xlfn.XLOOKUP($A7, tblRisposte[ItemKey], tblRisposte[Valore], "")="Non eseguito","X",0) -> 0 | V7: =IF((U7="X"),T7,0) -> 0 | W7: =COUNTIF(I7,"x")+COUNTIF(L7,"x")+COUNTIF(O7,"x")+COUNTIF(R7,"x")+COUNTIF(U7,"x") -> 0 | X7: =IF(COUNTIF(I7:U7,"X")=1,"OK","errore") -> errore | Y7: =IF(E7="SEP",IF(I7="x",H7,IF(L7="X",K7,IF(O7="x",N7,IF(R7="X",Q7,IF(U7="X",T7,""))))),"")
A8: =IF(G8<>"",ScenaAttiva&"_"&AB$4&TEXT(COUNTIF($G$3:G8,"<>"),"0000"),"") -> A_MAS0005 | B8: =IF(A8<>"",SquadraAttiva,"") -> 3 | C8: =IF(A8<>"",TEXT(B8,"0")&"-"&TRIM(A8),"") -> 3-A_MAS0005 | D8: =IFERROR(_xlfn.XLOOKUP(C8,tblRisposte[idValutazione],tblRisposte[Valore],""),"") -> 4 | F8: indirizza con oculatezza i soccorritori | G8: Standard | H8: {=_xlfn.LET(_xlpm.v,_xlfn.XLOOKUP(G8,tblValutazioni[TipoValutazione],tblValutazioni[MB],""),IF(_xlpm.v="","",_xlpm.v))} -> 5 | I8: =IF(_xlfn.XLOOKUP($A8, tblRisposte[ItemKey],tblRisposte[Valore],"")="Molto bene","X",0) -> 0 | J8: =IF((I8="X"),H8,0) -> 0 | K8: {=_xlfn.LET(_xlpm.v,_xlfn.XLOOKUP(G8,tblValutazioni[TipoValutazione],tblValutazioni[BE],""),IF(_xlpm.v="","",_xlpm.v))} -> 4 | L8: =IF(_xlfn.XLOOKUP($A8, tblRisposte[ItemKey], tblRisposte[Valore], "")="Bene", "X", 0) -> 0 | M8: =IF((L8="X"),K8,0) -> 0 | N8: {=_xlfn.LET(_xlpm.v,_xlfn.XLOOKUP(G8,tblValutazioni[TipoValutazione],tblValutazioni[SU],""),IF(_xlpm.v="","",_xlpm.v))} -> 2 | O8: =IF(_xlfn.XLOOKUP($A8, tblRisposte[ItemKey], tblRisposte[Valore], "")="Soddisfacente","X",0) -> 0 | P8: =IF((O8="X"),N8,0) -> 0 | Q8: {=_xlfn.LET(_xlpm.v,_xlfn.XLOOKUP(G8,tblValutazioni[TipoValutazione],tblValutazioni[IN],""),IF(_xlpm.v="","",_xlpm.v))} -> 1 | R8: =IF(_xlfn.XLOOKUP($A8, tblRisposte[ItemKey], tblRisposte[Valore], "")="Insufficiente","X",0) -> 0 | S8: =IF((R8="X"),Q8,0) -> 0 | T8: {=_xlfn.LET(_xlpm.v,_xlfn.XLOOKUP(G8,tblValutazioni[TipoValutazione],tblValutazioni[NE],""),IF(_xlpm.v="","",_xlpm.v))} -> 0 | U8: =IF(_xlfn.XLOOKUP($A8, tblRisposte[ItemKey], tblRisposte[Valore], "")="Non eseguito","X",0) -> 0 | V8: =IF((U8="X"),T8,0) -> 0 | W8: =COUNTIF(I8,"x")+COUNTIF(L8,"x")+COUNTIF(O8,"x")+COUNTIF(R8,"x")+COUNTIF(U8,"x") -> 0 | X8: =IF(COUNTIF(I8:U8,"X")=1,"OK","errore") -> errore | Y8: =IF(E8="SEP",IF(I8="x",H8,IF(L8="X",K8,IF(O8="x",N8,IF(R8="X",Q8,IF(U8="X",T8,""))))),"") | Z8: Master
A9: =IF(G9<>"",ScenaAttiva&"_"&AB$4&TEXT(COUNTIF($G$3:G9,"<>"),"0000"),"") -> A_MAS0006 | B9: =IF(A9<>"",SquadraAttiva,"") -> 3 | C9: =IF(A9<>"",TEXT(B9,"0")&"-"&TRIM(A9),"") -> 3-A_MAS0006 | D9: =IFERROR(_xlfn.XLOOKUP(C9,tblRisposte[idValutazione],tblRisposte[Valore],""),"") -> 4 | F9: atteggiamento cortese e determinato | G9: Standard | H9: {=_xlfn.LET(_xlpm.v,_xlfn.XLOOKUP(G9,tblValutazioni[TipoValutazione],tblValutazioni[MB],""),IF(_xlpm.v="","",_xlpm.v))} -> 5 | I9: =IF(_xlfn.XLOOKUP($A9, tblRisposte[ItemKey],tblRisposte[Valore],"")="Molto bene","X",0) -> 0 | J9: =IF((I9="X"),H9,0) -> 0 | K9: {=_xlfn.LET(_xlpm.v,_xlfn.XLOOKUP(G9,tblValutazioni[TipoValutazione],tblValutazioni[BE],""),IF(_xlpm.v="","",_xlpm.v))} -> 4 | L9: =IF(_xlfn.XLOOKUP($A9, tblRisposte[ItemKey], tblRisposte[Valore], "")="Bene", "X", 0) -> 0 | M9: =IF((L9="X"),K9,0) -> 0 | N9: {=_xlfn.LET(_xlpm.v,_xlfn.XLOOKUP(G9,tblValutazioni[TipoValutazione],tblValutazioni[SU],""),IF(_xlpm.v="","",_xlpm.v))} -> 2 | O9: =IF(_xlfn.XLOOKUP($A9, tblRisposte[ItemKey], tblRisposte[Valore], "")="Soddisfacente","X",0) -> 0 | P9: =IF((O9="X"),N9,0) -> 0 | Q9: {=_xlfn.LET(_xlpm.v,_xlfn.XLOOKUP(G9,tblValutazioni[TipoValutazione],tblValutazioni[IN],""),IF(_xlpm.v="","",_xlpm.v))} -> 1 | R9: =IF(_xlfn.XLOOKUP($A9, tblRisposte[ItemKey], tblRisposte[Valore], "")="Insufficiente","X",0) -> 0 | S9: =IF((R9="X"),Q9,0) -> 0 | T9: {=_xlfn.LET(_xlpm.v,_xlfn.XLOOKUP(G9,tblValutazioni[TipoValutazione],tblValutazioni[NE],""),IF(_xlpm.v="","",_xlpm.v))} -> 0 | U9: =IF(_xlfn.XLOOKUP($A9, tblRisposte[ItemKey], tblRisposte[Valore], "")="Non eseguito","X",0) -> 0 | V9: =IF((U9="X"),T9,0) -> 0 | W9: =COUNTIF(I9,"x")+COUNTIF(L9,"x")+COUNTIF(O9,"x")+COUNTIF(R9,"x")+COUNTIF(U9,"x") -> 0 | X9: =IF(COUNTIF(I9:U9,"X")=1,"OK","errore") -> errore | Y9: =IF(E9="SEP",IF(I9="x",H9,IF(L9="X",K9,IF(O9="x",N9,IF(R9="X",Q9,IF(U9="X",T9,""))))),"")
A10: =IF(G10<>"",ScenaAttiva&"_"&AB$4&TEXT(COUNTIF($G$3:G10,"<>"),"0000"),"") | B10: =IF(A10<>"",SquadraAttiva,"") | C10: =IF(A10<>"",TEXT(B10,"0")&"-"&TRIM(A10),"") | D10: =IFERROR(_xlfn.XLOOKUP(C10,tblRisposte[idValutazione],tblRisposte[Valore],""),"") | F10: CHIAMATA DI SOCCORSO | H10: {=_xlfn.LET(_xlpm.v,_xlfn.XLOOKUP(G10,tblValutazioni[TipoValutazione],tblValutazioni[MB],""),IF(_xlpm.v="","",_xlpm.v))} | I10: =IF(_xlfn.XLOOKUP($A10, tblRisposte[ItemKey],tblRisposte[Valore],"")="Molto bene","X",0) -> 0 | J10: =IF((I10="X"),H10,0) -> 0 | K10: {=_xlfn.LET(_xlpm.v,_xlfn.XLOOKUP(G10,tblValutazioni[TipoValutazione],tblValutazioni[BE],""),IF(_xlpm.v="","",_xlpm.v))} | L10: =IF(_xlfn.XLOOKUP($A10, tblRisposte[ItemKey], tblRisposte[Valore], "")="Bene", "X", 0) -> 0 | M10: =IF((L10="X"),K10,0) -> 0 | N10: {=_xlfn.LET(_xlpm.v,_xlfn.XLOOKUP(G10,tblValutazioni[TipoValutazione],tblValutazioni[SU],""),IF(_xlpm.v="","",_xlpm.v))} | O10: =IF(_xlfn.XLOOKUP($A10, tblRisposte[ItemKey], tblRisposte[Valore], "")="Soddisfacente","X",0) -> 0 | P10: =IF((O10="X"),N10,0) -> 0 | Q10: {=_xlfn.LET(_xlpm.v,_xlfn.XLOOKUP(G10,tblValutazioni[TipoValutazione],tblValutazioni[IN],""),IF(_xlpm.v="","",_xlpm.v))} | R10: =IF(_xlfn.XLOOKUP($A10, tblRisposte[ItemKey], tblRisposte[Valore], "")="Insufficiente","X",0) -> 0 | S10: =IF((R10="X"),Q10,0) -> 0 | T10: {=_xlfn.LET(_xlpm.v,_xlfn.XLOOKUP(G10,tblValutazioni[TipoValutazione],tblValutazioni[NE],""),IF(_xlpm.v="","",_xlpm.v))} | U10: =IF(_xlfn.XLOOKUP($A10, tblRisposte[ItemKey], tblRisposte[Valore], "")="Non eseguito","X",0) -> 0 | V10: =IF((U10="X"),T10,0) -> 0 | W10: =COUNTIF(I10,"x")+COUNTIF(L10,"x")+COUNTIF(O10,"x")+COUNTIF(R10,"x")+COUNTIF(U10,"x") -> 0 | X10: =IF(COUNTIF(I10:U10,"X")=1,"OK","errore") -> errore | Y10: =IF(E10="SEP",IF(I10="x",H10,IF(L10="X",K10,IF(O10="x",N10,IF(R10="X",Q10,IF(U10="X",T10,""))))),"")
A11: =IF(G11<>"",ScenaAttiva&"_"&AB$4&TEXT(COUNTIF($G$3:G11,"<>"),"0000"),"") -> A_MAS0007 | B11: =IF(A11<>"",SquadraAttiva,"") -> 3 | C11: =IF(A11<>"",TEXT(B11,"0")&"-"&TRIM(A11),"") -> 3-A_MAS0007 | D11: =IFERROR(_xlfn.XLOOKUP(C11,tblRisposte[idValutazione],tblRisposte[Valore],""),"") -> 1 | F11: fa la prima chiamata entro 2 minuti | G11: 3 Voci | H11: {=_xlfn.LET(_xlpm.v,_xlfn.XLOOKUP(G11,tblValutazioni[TipoValutazione],tblValutazioni[MB],""),IF(_xlpm.v="","",_xlpm.v))} -> 3 | I11: =IF(_xlfn.XLOOKUP($A11, tblRisposte[ItemKey],tblRisposte[Valore],"")="Molto bene","X",0) -> 0 | J11: =IF((I11="X"),H11,0) -> 0 | K11: {=_xlfn.LET(_xlpm.v,_xlfn.XLOOKUP(G11,tblValutazioni[TipoValutazione],tblValutazioni[BE],""),IF(_xlpm.v="","",_xlpm.v))} | L11: =IF(_xlfn.XLOOKUP($A11, tblRisposte[ItemKey], tblRisposte[Valore], "")="Bene", "X", 0) -> 0 | M11: =IF((L11="X"),K11,0) -> 0 | N11: {=_xlfn.LET(_xlpm.v,_xlfn.XLOOKUP(G11,tblValutazioni[TipoValutazione],tblValutazioni[SU],""),IF(_xlpm.v="","",_xlpm.v))} -> 1 | O11: =IF(_xlfn.XLOOKUP($A11, tblRisposte[ItemKey], tblRisposte[Valore], "")="Soddisfacente","X",0) -> 0 | P11: =IF((O11="X"),N11,0) -> 0 | Q11: {=_xlfn.LET(_xlpm.v,_xlfn.XLOOKUP(G11,tblValutazioni[TipoValutazione],tblValutazioni[IN],""),IF(_xlpm.v="","",_xlpm.v))} | R11: =IF(_xlfn.XLOOKUP($A11, tblRisposte[ItemKey], tblRisposte[Valore], "")="Insufficiente","X",0) -> 0 | S11: =IF((R11="X"),Q11,0) -> 0 | T11: {=_xlfn.LET(_xlpm.v,_xlfn.XLOOKUP(G11,tblValutazioni[TipoValutazione],tblValutazioni[NE],""),IF(_xlpm.v="","",_xlpm.v))} -> 0 | U11: =IF(_xlfn.XLOOKUP($A11, tblRisposte[ItemKey], tblRisposte[Valore], "")="Non eseguito","X",0) -> 0 | V11: =IF((U11="X"),T11,0) -> 0 | W11: =COUNTIF(I11,"x")+COUNTIF(L11,"x")+COUNTIF(O11,"x")+COUNTIF(R11,"x")+COUNTIF(U11,"x") -> 0 | X11: =IF(COUNTIF(I11:U11,"X")=1,"OK","errore") -> errore | Y11: =IF(E11="SEP",IF(I11="x",H11,IF(L11="X",K11,IF(O11="x",N11,IF(R11="X",Q11,IF(U11="X",T11,""))))),"") | Z11: Scheda piena | AA11: =SUM(H2:H41) -> 120
A12: =IF(G12<>"",ScenaAttiva&"_"&AB$4&TEXT(COUNTIF($G$3:G12,"<>"),"0000"),"") -> A_MAS0008 | B12: =IF(A12<>"",SquadraAttiva,"") -> 3 | C12: =IF(A12<>"",TEXT(B12,"0")&"-"&TRIM(A12),"") -> 3-A_MAS0008 | D12: =IFERROR(_xlfn.XLOOKUP(C12,tblRisposte[idValutazione],tblRisposte[Valore],""),"") -> 4 | F12: si identifica /presenta | G12: Standard | H12: {=_xlfn.LET(_xlpm.v,_xlfn.XLOOKUP(G12,tblValutazioni[TipoValutazione],tblValutazioni[MB],""),IF(_xlpm.v="","",_xlpm.v))} -> 5 | I12: =IF(_xlfn.XLOOKUP($A12, tblRisposte[ItemKey],tblRisposte[Valore],"")="Molto bene","X",0) -> 0 | J12: =IF((I12="X"),H12,0) -> 0 | K12: {=_xlfn.LET(_xlpm.v,_xlfn.XLOOKUP(G12,tblValutazioni[TipoValutazione],tblValutazioni[BE],""),IF(_xlpm.v="","",_xlpm.v))} -> 4 | L12: =IF(_xlfn.XLOOKUP($A12, tblRisposte[ItemKey], tblRisposte[Valore], "")="Bene", "X", 0) -> 0 | M12: =IF((L12="X"),K12,0) -> 0 | N12: {=_xlfn.LET(_xlpm.v,_xlfn.XLOOKUP(G12,tblValutazioni[TipoValutazione],tblValutazioni[SU],""),IF(_xlpm.v="","",_xlpm.v))} -> 2 | O12: =IF(_xlfn.XLOOKUP($A12, tblRisposte[ItemKey], tblRisposte[Valore], "")="Soddisfacente","X",0) -> 0 | P12: =IF((O12="X"),N12,0) -> 0 | Q12: {=_xlfn.LET(_xlpm.v,_xlfn.XLOOKUP(G12,tblValutazioni[TipoValutazione],tblValutazioni[IN],""),IF(_xlpm.v="","",_xlpm.v))} -> 1 | R12: =IF(_xlfn.XLOOKUP($A12, tblRisposte[ItemKey], tblRisposte[Valore], "")="Insufficiente","X",0) -> 0 | S12: =IF((R12="X"),Q12,0) -> 0 | T12: {=_xlfn.LET(_xlpm.v,_xlfn.XLOOKUP(G12,tblValutazioni[TipoValutazione],tblValutazioni[NE],""),IF(_xlpm.v="","",_xlpm.v))} -> 0 | U12: =IF(_xlfn.XLOOKUP($A12, tblRisposte[ItemKey], tblRisposte[Valore], "")="Non eseguito","X",0) -> 0 | V12: =IF((U12="X"),T12,0) -> 0 | W12: =COUNTIF(I12,"x")+COUNTIF(L12,"x")+COUNTIF(O12,"x")+COUNTIF(R12,"x")+COUNTIF(U12,"x") -> 0 | X12: =IF(COUNTIF(I12:U12,"X")=1,"OK","errore") -> errore | Y12: =IF(E12="SEP",IF(I12="x",H12,IF(L12="X",K12,IF(O12="x",N12,IF(R12="X",Q12,IF(U12="X",T12,""))))),"") | Z12: realizzato | AA12: =J43/AA11 -> 0
A13: =IF(G13<>"",ScenaAttiva&"_"&AB$4&TEXT(COUNTIF($G$3:G13,"<>"),"0000"),"") -> A_MAS0009 | B13: =IF(A13<>"",SquadraAttiva,"") -> 3 | C13: =IF(A13<>"",TEXT(B13,"0")&"-"&TRIM(A13),"") -> 3-A_MAS0009 | D13: =IFERROR(_xlfn.XLOOKUP(C13,tblRisposte[idValutazione],tblRisposte[Valore],""),"") -> 1 | F13: spiega da dove chiama e indica come raggiungere il luogo | G13: 3 Voci | H13: {=_xlfn.LET(_xlpm.v,_xlfn.XLOOKUP(G13,tblValutazioni[TipoValutazione],tblValutazioni[MB],""),IF(_xlpm.v="","",_xlpm.v))} -> 3 | I13: =IF(_xlfn.XLOOKUP($A13, tblRisposte[ItemKey],tblRisposte[Valore],"")="Molto bene","X",0) -> 0 | J13: =IF((I13="X"),H13,0) -> 0 | K13: {=_xlfn.LET(_xlpm.v,_xlfn.XLOOKUP(G13,tblValutazioni[TipoValutazione],tblValutazioni[BE],""),IF(_xlpm.v="","",_xlpm.v))} | L13: =IF(_xlfn.XLOOKUP($A13, tblRisposte[ItemKey], tblRisposte[Valore], "")="Bene", "X", 0) -> 0 | M13: =IF((L13="X"),K13,0) -> 0 | N13: {=_xlfn.LET(_xlpm.v,_xlfn.XLOOKUP(G13,tblValutazioni[TipoValutazione],tblValutazioni[SU],""),IF(_xlpm.v="","",_xlpm.v))} -> 1 | O13: =IF(_xlfn.XLOOKUP($A13, tblRisposte[ItemKey], tblRisposte[Valore], "")="Soddisfacente","X",0) -> 0 | P13: =IF((O13="X"),N13,0) -> 0 | Q13: {=_xlfn.LET(_xlpm.v,_xlfn.XLOOKUP(G13,tblValutazioni[TipoValutazione],tblValutazioni[IN],""),IF(_xlpm.v="","",_xlpm.v))} | R13: =IF(_xlfn.XLOOKUP($A13, tblRisposte[ItemKey], tblRisposte[Valore], "")="Insufficiente","X",0) -> 0 | S13: =IF((R13="X"),Q13,0) -> 0 | T13: {=_xlfn.LET(_xlpm.v,_xlfn.XLOOKUP(G13,tblValutazioni[TipoValutazione],tblValutazioni[NE],""),IF(_xlpm.v="","",_xlpm.v))} -> 0 | U13: =IF(_xlfn.XLOOKUP($A13, tblRisposte[ItemKey], tblRisposte[Valore], "")="Non eseguito","X",0) -> 0 | V13: =IF((U13="X"),T13,0) -> 0 | W13: =COUNTIF(I13,"x")+COUNTIF(L13,"x")+COUNTIF(O13,"x")+COUNTIF(R13,"x")+COUNTIF(U13,"x") -> 0 | X13: =IF(COUNTIF(I13:U13,"X")=1,"OK","errore") -> errore | Y13: =IF(E13="SEP",IF(I13="x",H13,IF(L13="X",K13,IF(O13="x",N13,IF(R13="X",Q13,IF(U13="X",T13,""))))),"")
A14: =IF(G14<>"",ScenaAttiva&"_"&AB$4&TEXT(COUNTIF($G$3:G14,"<>"),"0000"),"") -> A_MAS0010 | B14: =IF(A14<>"",SquadraAttiva,"") -> 3 | C14: =IF(A14<>"",TEXT(B14,"0")&"-"&TRIM(A14),"") -> 3-A_MAS0010 | D14: =IFERROR(_xlfn.XLOOKUP(C14,tblRisposte[idValutazione],tblRisposte[Valore],""),"") -> 1 | F14: descrive l’evento | G14: Standard | H14: {=_xlfn.LET(_xlpm.v,_xlfn.XLOOKUP(G14,tblValutazioni[TipoValutazione],tblValutazioni[MB],""),IF(_xlpm.v="","",_xlpm.v))} -> 5 | I14: =IF(_xlfn.XLOOKUP($A14, tblRisposte[ItemKey],tblRisposte[Valore],"")="Molto bene","X",0) -> 0 | J14: =IF((I14="X"),H14,0) -> 0 | K14: {=_xlfn.LET(_xlpm.v,_xlfn.XLOOKUP(G14,tblValutazioni[TipoValutazione],tblValutazioni[BE],""),IF(_xlpm.v="","",_xlpm.v))} -> 4 | L14: =IF(_xlfn.XLOOKUP($A14, tblRisposte[ItemKey], tblRisposte[Valore], "")="Bene", "X", 0) -> 0 | M14: =IF((L14="X"),K14,0) -> 0 | N14: {=_xlfn.LET(_xlpm.v,_xlfn.XLOOKUP(G14,tblValutazioni[TipoValutazione],tblValutazioni[SU],""),IF(_xlpm.v="","",_xlpm.v))} -> 2 | O14: =IF(_xlfn.XLOOKUP($A14, tblRisposte[ItemKey], tblRisposte[Valore], "")="Soddisfacente","X",0) -> 0 | P14: =IF((O14="X"),N14,0) -> 0 | Q14: {=_xlfn.LET(_xlpm.v,_xlfn.XLOOKUP(G14,tblValutazioni[TipoValutazione],tblValutazioni[IN],""),IF(_xlpm.v="","",_xlpm.v))} -> 1 | R14: =IF(_xlfn.XLOOKUP($A14, tblRisposte[ItemKey], tblRisposte[Valore], "")="Insufficiente","X",0) -> 0 | S14: =IF((R14="X"),Q14,0) -> 0 | T14: {=_xlfn.LET(_xlpm.v,_xlfn.XLOOKUP(G14,tblValutazioni[TipoValutazione],tblValutazioni[NE],""),IF(_xlpm.v="","",_xlpm.v))} -> 0 | U14: =IF(_xlfn.XLOOKUP($A14, tblRisposte[ItemKey], tblRisposte[Valore], "")="Non eseguito","X",0) -> 0 | V14: =IF((U14="X"),T14,0) -> 0 | W14: =COUNTIF(I14,"x")+COUNTIF(L14,"x")+COUNTIF(O14,"x")+COUNTIF(R14,"x")+COUNTIF(U14,"x") -> 0 | X14: =IF(COUNTIF(I14:U14,"X")=1,"OK","errore") -> errore | Y14: =IF(E14="SEP",IF(I14="x",H14,IF(L14="X",K14,IF(O14="x",N14,IF(R14="X",Q14,IF(U14="X",T14,""))))),"") | Z14: SEP PIENO | AA14: =SUMIF(E2:E41,"SEP",H2:H41) -> 35
A15: =IF(G15<>"",ScenaAttiva&"_"&AB$4&TEXT(COUNTIF($G$3:G15,"<>"),"0000"),"") -> A_MAS0011 | B15: =IF(A15<>"",SquadraAttiva,"") -> 3 | C15: =IF(A15<>"",TEXT(B15,"0")&"-"&TRIM(A15),"") -> 3-A_MAS0011 | D15: =IFERROR(_xlfn.XLOOKUP(C15,tblRisposte[idValutazione],tblRisposte[Valore],""),"") -> 3 | F15: 1 - Bambino PBLS -ACC Cardiopatcio | G15: 3 Voci | H15: {=_xlfn.LET(_xlpm.v,_xlfn.XLOOKUP(G15,tblValutazioni[TipoValutazione],tblValutazioni[MB],""),IF(_xlpm.v="","",_xlpm.v))} -> 3 | I15: =IF(_xlfn.XLOOKUP($A15, tblRisposte[ItemKey],tblRisposte[Valore],"")="Molto bene","X",0) -> 0 | J15: =IF((I15="X"),H15,0) -> 0 | K15: {=_xlfn.LET(_xlpm.v,_xlfn.XLOOKUP(G15,tblValutazioni[TipoValutazione],tblValutazioni[BE],""),IF(_xlpm.v="","",_xlpm.v))} | L15: =IF(_xlfn.XLOOKUP($A15, tblRisposte[ItemKey], tblRisposte[Valore], "")="Bene", "X", 0) -> 0 | M15: =IF((L15="X"),K15,0) -> 0 | N15: {=_xlfn.LET(_xlpm.v,_xlfn.XLOOKUP(G15,tblValutazioni[TipoValutazione],tblValutazioni[SU],""),IF(_xlpm.v="","",_xlpm.v))} -> 1 | O15: =IF(_xlfn.XLOOKUP($A15, tblRisposte[ItemKey], tblRisposte[Valore], "")="Soddisfacente","X",0) -> 0 | P15: =IF((O15="X"),N15,0) -> 0 | Q15: {=_xlfn.LET(_xlpm.v,_xlfn.XLOOKUP(G15,tblValutazioni[TipoValutazione],tblValutazioni[IN],""),IF(_xlpm.v="","",_xlpm.v))} | R15: =IF(_xlfn.XLOOKUP($A15, tblRisposte[ItemKey], tblRisposte[Valore], "")="Insufficiente","X",0) -> 0 | S15: =IF((R15="X"),Q15,0) -> 0 | T15: {=_xlfn.LET(_xlpm.v,_xlfn.XLOOKUP(G15,tblValutazioni[TipoValutazione],tblValutazioni[NE],""),IF(_xlpm.v="","",_xlpm.v))} -> 0 | U15: =IF(_xlfn.XLOOKUP($A15, tblRisposte[ItemKey], tblRisposte[Valore], "")="Non eseguito","X",0) -> 0 | V15: =IF((U15="X"),T15,0) -> 0 | W15: =COUNTIF(I15,"x")+COUNTIF(L15,"x")+COUNTIF(O15,"x")+COUNTIF(R15,"x")+COUNTIF(U15,"x") -> 0 | X15: =IF(COUNTIF(I15:U15,"X")=1,"OK","errore") -> errore | Y15: =IF(E15="SEP",IF(I15="x",H15,IF(L15="X",K15,IF(O15="x",N15,IF(R15="X",Q15,IF(U15="X",T15,""))))),"")
A16: =IF(G16<>"",ScenaAttiva&"_"&AB$4&TEXT(COUNTIF($G$3:G16,"<>"),"0000"),"") -> A_MAS0012 | B16: =IF(A16<>"",SquadraAttiva,"") -> 3 | C16: =IF(A16<>"",TEXT(B16,"0")&"-"&TRIM(A16),"") -> 3-A_MAS0012 | D16: =IFERROR(_xlfn.XLOOKUP(C16,tblRisposte[idValutazione],tblRisposte[Valore],""),"") -> 3 | F16: 2 – Ragazzo Tossicodipendete con siringa | G16: 3 Voci | H16: {=_xlfn.LET(_xlpm.v,_xlfn.XLOOKUP(G16,tblValutazioni[TipoValutazione],tblValutazioni[MB],""),IF(_xlpm.v="","",_xlpm.v))} -> 3 | I16: =IF(_xlfn.XLOOKUP($A16, tblRisposte[ItemKey],tblRisposte[Valore],"")="Molto bene","X",0) -> 0 | J16: =IF((I16="X"),H16,0) -> 0 | K16: {=_xlfn.LET(_xlpm.v,_xlfn.XLOOKUP(G16,tblValutazioni[TipoValutazione],tblValutazioni[BE],""),IF(_xlpm.v="","",_xlpm.v))} | L16: =IF(_xlfn.XLOOKUP($A16, tblRisposte[ItemKey], tblRisposte[Valore], "")="Bene", "X", 0) -> 0 | M16: =IF((L16="X"),K16,0) -> 0 | N16: {=_xlfn.LET(_xlpm.v,_xlfn.XLOOKUP(G16,tblValutazioni[TipoValutazione],tblValutazioni[SU],""),IF(_xlpm.v="","",_xlpm.v))} -> 1 | O16: =IF(_xlfn.XLOOKUP($A16, tblRisposte[ItemKey], tblRisposte[Valore], "")="Soddisfacente","X",0) -> 0 | P16: =IF((O16="X"),N16,0) -> 0 | Q16: {=_xlfn.LET(_xlpm.v,_xlfn.XLOOKUP(G16,tblValutazioni[TipoValutazione],tblValutazioni[IN],""),IF(_xlpm.v="","",_xlpm.v))} | R16: =IF(_xlfn.XLOOKUP($A16, tblRisposte[ItemKey], tblRisposte[Valore], "")="Insufficiente","X",0) -> 0 | S16: =IF((R16="X"),Q16,0) -> 0 | T16: {=_xlfn.LET(_xlpm.v,_xlfn.XLOOKUP(G16,tblValutazioni[TipoValutazione],tblValutazioni[NE],""),IF(_xlpm.v="","",_xlpm.v))} -> 0 | U16: =IF(_xlfn.XLOOKUP($A16, tblRisposte[ItemKey], tblRisposte[Valore], "")="Non eseguito","X",0) -> 0 | V16: =IF((U16="X"),T16,0) -> 0 | W16: =COUNTIF(I16,"x")+COUNTIF(L16,"x")+COUNTIF(O16,"x")+COUNTIF(R16,"x")+COUNTIF(U16,"x") -> 0 | X16: =IF(COUNTIF(I16:U16,"X")=1,"OK","errore") -> errore | Y16: =IF(E16="SEP",IF(I16="x",H16,IF(L16="X",K16,IF(O16="x",N16,IF(R16="X",Q16,IF(U16="X",T16,""))))),"")
A17: =IF(G17<>"",ScenaAttiva&"_"&AB$4&TEXT(COUNTIF($G$3:G17,"<>"),"0000"),"") -> A_MAS0013 | B17: =IF(A17<>"",SquadraAttiva,"") -> 3 | C17: =IF(A17<>"",TEXT(B17,"0")&"-"&TRIM(A17),"") -> 3-A_MAS0013 | D17: =IFERROR(_xlfn.XLOOKUP(C17,tblRisposte[idValutazione],tblRisposte[Valore],""),"") -> 3 | F17: 3 – Padre Trauma Cranico | G17: 3 Voci | H17: {=_xlfn.LET(_xlpm.v,_xlfn.XLOOKUP(G17,tblValutazioni[TipoValutazione],tblValutazioni[MB],""),IF(_xlpm.v="","",_xlpm.v))} -> 3 | I17: =IF(_xlfn.XLOOKUP($A17, tblRisposte[ItemKey],tblRisposte[Valore],"")="Molto bene","X",0) -> 0 | J17: =IF((I17="X"),H17,0) -> 0 | K17: {=_xlfn.LET(_xlpm.v,_xlfn.XLOOKUP(G17,tblValutazioni[TipoValutazione],tblValutazioni[BE],""),IF(_xlpm.v="","",_xlpm.v))} | L17: =IF(_xlfn.XLOOKUP($A17, tblRisposte[ItemKey], tblRisposte[Valore], "")="Bene", "X", 0) -> 0 | M17: =IF((L17="X"),K17,0) -> 0 | N17: {=_xlfn.LET(_xlpm.v,_xlfn.XLOOKUP(G17,tblValutazioni[TipoValutazione],tblValutazioni[SU],""),IF(_xlpm.v="","",_xlpm.v))} -> 1 | O17: =IF(_xlfn.XLOOKUP($A17, tblRisposte[ItemKey], tblRisposte[Valore], "")="Soddisfacente","X",0) -> 0 | P17: =IF((O17="X"),N17,0) -> 0 | Q17: {=_xlfn.LET(_xlpm.v,_xlfn.XLOOKUP(G17,tblValutazioni[TipoValutazione],tblValutazioni[IN],""),IF(_xlpm.v="","",_xlpm.v))} | R17: =IF(_xlfn.XLOOKUP($A17, tblRisposte[ItemKey], tblRisposte[Valore], "")="Insufficiente","X",0) -> 0 | S17: =IF((R17="X"),Q17,0) -> 0 | T17: {=_xlfn.LET(_xlpm.v,_xlfn.XLOOKUP(G17,tblValutazioni[TipoValutazione],tblValutazioni[NE],""),IF(_xlpm.v="","",_xlpm.v))} -> 0 | U17: =IF(_xlfn.XLOOKUP($A17, tblRisposte[ItemKey], tblRisposte[Valore], "")="Non eseguito","X",0) -> 0 | V17: =IF((U17="X"),T17,0) -> 0 | W17: =COUNTIF(I17,"x")+COUNTIF(L17,"x")+COUNTIF(O17,"x")+COUNTIF(R17,"x")+COUNTIF(U17,"x") -> 0 | X17: =IF(COUNTIF(I17:U17,"X")=1,"OK","errore") -> errore | Y17: =IF(E17="SEP",IF(I17="x",H17,IF(L17="X",K17,IF(O17="x",N17,IF(R17="X",Q17,IF(U17="X",T17,""))))),"")
A18: =IF(G18<>"",ScenaAttiva&"_"&AB$4&TEXT(COUNTIF($G$3:G18,"<>"),"0000"),"") -> A_MAS0014 | B18: =IF(A18<>"",SquadraAttiva,"") -> 3 | C18: =IF(A18<>"",TEXT(B18,"0")&"-"&TRIM(A18),"") -> 3-A_MAS0014 | D18: =IFERROR(_xlfn.XLOOKUP(C18,tblRisposte[idValutazione],tblRisposte[Valore],""),"") -> 0 | F18: 4 – Bidella attacco d'asma | G18: 3 Voci | H18: {=_xlfn.LET(_xlpm.v,_xlfn.XLOOKUP(G18,tblValutazioni[TipoValutazione],tblValutazioni[MB],""),IF(_xlpm.v="","",_xlpm.v))} -> 3 | I18: =IF(_xlfn.XLOOKUP($A18, tblRisposte[ItemKey],tblRisposte[Valore],"")="Molto bene","X",0) -> 0 | J18: =IF((I18="X"),H18,0) -> 0 | K18: {=_xlfn.LET(_xlpm.v,_xlfn.XLOOKUP(G18,tblValutazioni[TipoValutazione],tblValutazioni[BE],""),IF(_xlpm.v="","",_xlpm.v))} | L18: =IF(_xlfn.XLOOKUP($A18, tblRisposte[ItemKey], tblRisposte[Valore], "")="Bene", "X", 0) -> 0 | M18: =IF((L18="X"),K18,0) -> 0 | N18: {=_xlfn.LET(_xlpm.v,_xlfn.XLOOKUP(G18,tblValutazioni[TipoValutazione],tblValutazioni[SU],""),IF(_xlpm.v="","",_xlpm.v))} -> 1 | O18: =IF(_xlfn.XLOOKUP($A18, tblRisposte[ItemKey], tblRisposte[Valore], "")="Soddisfacente","X",0) -> 0 | P18: =IF((O18="X"),N18,0) -> 0 | Q18: {=_xlfn.LET(_xlpm.v,_xlfn.XLOOKUP(G18,tblValutazioni[TipoValutazione],tblValutazioni[IN],""),IF(_xlpm.v="","",_xlpm.v))} | R18: =IF(_xlfn.XLOOKUP($A18, tblRisposte[ItemKey], tblRisposte[Valore], "")="Insufficiente","X",0) -> 0 | S18: =IF((R18="X"),Q18,0) -> 0 | T18: {=_xlfn.LET(_xlpm.v,_xlfn.XLOOKUP(G18,tblValutazioni[TipoValutazione],tblValutazioni[NE],""),IF(_xlpm.v="","",_xlpm.v))} -> 0 | U18: =IF(_xlfn.XLOOKUP($A18, tblRisposte[ItemKey], tblRisposte[Valore], "")="Non eseguito","X",0) -> 0 | V18: =IF((U18="X"),T18,0) -> 0 | W18: =COUNTIF(I18,"x")+COUNTIF(L18,"x")+COUNTIF(O18,"x")+COUNTIF(R18,"x")+COUNTIF(U18,"x") -> 0 | X18: =IF(COUNTIF(I18:U18,"X")=1,"OK","errore") -> errore | Y18: =IF(E18="SEP",IF(I18="x",H18,IF(L18="X",K18,IF(O18="x",N18,IF(R18="X",Q18,IF(U18="X",T18,""))))),"")
A19: =IF(G19<>"",ScenaAttiva&"_"&AB$4&TEXT(COUNTIF($G$3:G19,"<>"),"0000"),"") -> A_MAS0015 | B19: =IF(A19<>"",SquadraAttiva,"") -> 3 | C19: =IF(A19<>"",TEXT(B19,"0")&"-"&TRIM(A19),"") -> 3-A_MAS0015 | D19: =IFERROR(_xlfn.XLOOKUP(C19,tblRisposte[idValutazione],tblRisposte[Valore],""),"") -> 1 | F19: 5 - Madre agitata (al telfono) | G19: 3 Voci | H19: {=_xlfn.LET(_xlpm.v,_xlfn.XLOOKUP(G19,tblValutazioni[TipoValutazione],tblValutazioni[MB],""),IF(_xlpm.v="","",_xlpm.v))} -> 3 | I19: =IF(_xlfn.XLOOKUP($A19, tblRisposte[ItemKey],tblRisposte[Valore],"")="Molto bene","X",0) -> 0 | J19: =IF((I19="X"),H19,0) -> 0 | K19: {=_xlfn.LET(_xlpm.v,_xlfn.XLOOKUP(G19,tblValutazioni[TipoValutazione],tblValutazioni[BE],""),IF(_xlpm.v="","",_xlpm.v))} | L19: =IF(_xlfn.XLOOKUP($A19, tblRisposte[ItemKey], tblRisposte[Valore], "")="Bene", "X", 0) -> 0 | M19: =IF((L19="X"),K19,0) -> 0 | N19: {=_xlfn.LET(_xlpm.v,_xlfn.XLOOKUP(G19,tblValutazioni[TipoValutazione],tblValutazioni[SU],""),IF(_xlpm.v="","",_xlpm.v))} -> 1 | O19: =IF(_xlfn.XLOOKUP($A19, tblRisposte[ItemKey], tblRisposte[Valore], "")="Soddisfacente","X",0) -> 0 | P19: =IF((O19="X"),N19,0) -> 0 | Q19: {=_xlfn.LET(_xlpm.v,_xlfn.XLOOKUP(G19,tblValutazioni[TipoValutazione],tblValutazioni[IN],""),IF(_xlpm.v="","",_xlpm.v))} | R19: =IF(_xlfn.XLOOKUP($A19, tblRisposte[ItemKey], tblRisposte[Valore], "")="Insufficiente","X",0) -> 0 | S19: =IF((R19="X"),Q19,0) -> 0 | T19: {=_xlfn.LET(_xlpm.v,_xlfn.XLOOKUP(G19,tblValutazioni[TipoValutazione],tblValutazioni[NE],""),IF(_xlpm.v="","",_xlpm.v))} -> 0 | U19: =IF(_xlfn.XLOOKUP($A19, tblRisposte[ItemKey], tblRisposte[Valore], "")="Non eseguito","X",0) -> 0 | V19: =IF((U19="X"),T19,0) -> 0 | W19: =COUNTIF(I19,"x")+COUNTIF(L19,"x")+COUNTIF(O19,"x")+COUNTIF(R19,"x")+COUNTIF(U19,"x") -> 0 | X19: =IF(COUNTIF(I19:U19,"X")=1,"OK","errore") -> errore
A20: =IF(G20<>"",ScenaAttiva&"_"&AB$4&TEXT(COUNTIF($G$3:G20,"<>"),"0000"),"") -> A_MAS0016 | B20: =IF(A20<>"",SquadraAttiva,"") -> 3 | C20: =IF(A20<>"",TEXT(B20,"0")&"-"&TRIM(A20),"") -> 3-A_MAS0016 | D20: =IFERROR(_xlfn.XLOOKUP(C20,tblRisposte[idValutazione],tblRisposte[Valore],""),"") -> 4 | F20: chiede intervento di mezzi di soccorso e automedica | G20: Standard | H20: {=_xlfn.LET(_xlpm.v,_xlfn.XLOOKUP(G20,tblValutazioni[TipoValutazione],tblValutazioni[MB],""),IF(_xlpm.v="","",_xlpm.v))} -> 5 | I20: =IF(_xlfn.XLOOKUP($A20, tblRisposte[ItemKey],tblRisposte[Valore],"")="Molto bene","X",0) -> 0 | J20: =IF((I20="X"),H20,0) -> 0 | K20: {=_xlfn.LET(_xlpm.v,_xlfn.XLOOKUP(G20,tblValutazioni[TipoValutazione],tblValutazioni[BE],""),IF(_xlpm.v="","",_xlpm.v))} -> 4 | L20: =IF(_xlfn.XLOOKUP($A20, tblRisposte[ItemKey], tblRisposte[Valore], "")="Bene", "X", 0) -> 0 | M20: =IF((L20="X"),K20,0) -> 0 | N20: {=_xlfn.LET(_xlpm.v,_xlfn.XLOOKUP(G20,tblValutazioni[TipoValutazione],tblValutazioni[SU],""),IF(_xlpm.v="","",_xlpm.v))} -> 2 | O20: =IF(_xlfn.XLOOKUP($A20, tblRisposte[ItemKey], tblRisposte[Valore], "")="Soddisfacente","X",0) -> 0 | P20: =IF((O20="X"),N20,0) -> 0 | Q20: {=_xlfn.LET(_xlpm.v,_xlfn.XLOOKUP(G20,tblValutazioni[TipoValutazione],tblValutazioni[IN],""),IF(_xlpm.v="","",_xlpm.v))} -> 1 | R20: =IF(_xlfn.XLOOKUP($A20, tblRisposte[ItemKey], tblRisposte[Valore], "")="Insufficiente","X",0) -> 0 | S20: =IF((R20="X"),Q20,0) -> 0 | T20: {=_xlfn.LET(_xlpm.v,_xlfn.XLOOKUP(G20,tblValutazioni[TipoValutazione],tblValutazioni[NE],""),IF(_xlpm.v="","",_xlpm.v))} -> 0 | U20: =IF(_xlfn.XLOOKUP($A20, tblRisposte[ItemKey], tblRisposte[Valore], "")="Non eseguito","X",0) -> 0 | V20: =IF((U20="X"),T20,0) -> 0 | W20: =COUNTIF(I20,"x")+COUNTIF(L20,"x")+COUNTIF(O20,"x")+COUNTIF(R20,"x")+COUNTIF(U20,"x") -> 0 | X20: =IF(COUNTIF(I20:U20,"X")=1,"OK","errore") -> errore | Y20: =IF(E20="SEP",IF(I20="x",H20,IF(L20="X",K20,IF(O20="x",N20,IF(R20="X",Q20,IF(U20="X",T20,""))))),"")
A21: =IF(G21<>"",ScenaAttiva&"_"&AB$4&TEXT(COUNTIF($G$3:G21,"<>"),"0000"),"") | B21: =IF(A21<>"",SquadraAttiva,"") | C21: =IF(A21<>"",TEXT(B21,"0")&"-"&TRIM(A21),"") | D21: =IFERROR(_xlfn.XLOOKUP(C21,tblRisposte[idValutazione],tblRisposte[Valore],""),"") | F21: ATTITUDINI DEL CAPO SQUADRA | H21: {=_xlfn.LET(_xlpm.v,_xlfn.XLOOKUP(G21,tblValutazioni[TipoValutazione],tblValutazioni[MB],""),IF(_xlpm.v="","",_xlpm.v))} | I21: =IF(_xlfn.XLOOKUP($A21, tblRisposte[ItemKey],tblRisposte[Valore],"")="Molto bene","X",0) -> 0 | J21: =IF((I21="X"),H21,0) -> 0 | K21: {=_xlfn.LET(_xlpm.v,_xlfn.XLOOKUP(G21,tblValutazioni[TipoValutazione],tblValutazioni[BE],""),IF(_xlpm.v="","",_xlpm.v))} | L21: =IF(_xlfn.XLOOKUP($A21, tblRisposte[ItemKey], tblRisposte[Valore], "")="Bene", "X", 0) -> 0 | M21: =IF((L21="X"),K21,0) -> 0 | N21: {=_xlfn.LET(_xlpm.v,_xlfn.XLOOKUP(G21,tblValutazioni[TipoValutazione],tblValutazioni[SU],""),IF(_xlpm.v="","",_xlpm.v))} | O21: =IF(_xlfn.XLOOKUP($A21, tblRisposte[ItemKey], tblRisposte[Valore], "")="Soddisfacente","X",0) -> 0 | P21: =IF((O21="X"),N21,0) -> 0 | Q21: {=_xlfn.LET(_xlpm.v,_xlfn.XLOOKUP(G21,tblValutazioni[TipoValutazione],tblValutazioni[IN],""),IF(_xlpm.v="","",_xlpm.v))} | R21: =IF(_xlfn.XLOOKUP($A21, tblRisposte[ItemKey], tblRisposte[Valore], "")="Insufficiente","X",0) -> 0 | S21: =IF((R21="X"),Q21,0) -> 0 | T21: {=_xlfn.LET(_xlpm.v,_xlfn.XLOOKUP(G21,tblValutazioni[TipoValutazione],tblValutazioni[NE],""),IF(_xlpm.v="","",_xlpm.v))} | U21: =IF(_xlfn.XLOOKUP($A21, tblRisposte[ItemKey], tblRisposte[Valore], "")="Non eseguito","X",0) -> 0 | V21: =IF((U21="X"),T21,0) -> 0 | W21: =COUNTIF(I21,"x")+COUNTIF(L21,"x")+COUNTIF(O21,"x")+COUNTIF(R21,"x")+COUNTIF(U21,"x") -> 0 | X21: =IF(COUNTIF(I21:U21,"X")=1,"OK","errore") -> errore | Y21: =IF(E21="SEP",IF(I21="x",H21,IF(L21="X",K21,IF(O21="x",N21,IF(R21="X",Q21,IF(U21="X",T21,""))))),"")
A22: =IF(G22<>"",ScenaAttiva&"_"&AB$4&TEXT(COUNTIF($G$3:G22,"<>"),"0000"),"") -> A_MAS0017 | B22: =IF(A22<>"",SquadraAttiva,"") -> 3 | C22: =IF(A22<>"",TEXT(B22,"0")&"-"&TRIM(A22),"") -> 3-A_MAS0017 | D22: =IFERROR(_xlfn.XLOOKUP(C22,tblRisposte[idValutazione],tblRisposte[Valore],""),"") -> 4 | E22: SEP | F22: determina ruoli e competenze | G22: Standard | H22: {=_xlfn.LET(_xlpm.v,_xlfn.XLOOKUP(G22,tblValutazioni[TipoValutazione],tblValutazioni[MB],""),IF(_xlpm.v="","",_xlpm.v))} -> 5 | I22: =IF(_xlfn.XLOOKUP($A22, tblRisposte[ItemKey],tblRisposte[Valore],"")="Molto bene","X",0) -> 0 | J22: =IF((I22="X"),H22,0) -> 0 | K22: {=_xlfn.LET(_xlpm.v,_xlfn.XLOOKUP(G22,tblValutazioni[TipoValutazione],tblValutazioni[BE],""),IF(_xlpm.v="","",_xlpm.v))} -> 4 | L22: =IF(_xlfn.XLOOKUP($A22, tblRisposte[ItemKey], tblRisposte[Valore], "")="Bene", "X", 0) -> 0 | M22: =IF((L22="X"),K22,0) -> 0 | N22: {=_xlfn.LET(_xlpm.v,_xlfn.XLOOKUP(G22,tblValutazioni[TipoValutazione],tblValutazioni[SU],""),IF(_xlpm.v="","",_xlpm.v))} -> 2 | O22: =IF(_xlfn.XLOOKUP($A22, tblRisposte[ItemKey], tblRisposte[Valore], "")="Soddisfacente","X",0) -> 0 | P22: =IF((O22="X"),N22,0) -> 0 | Q22: {=_xlfn.LET(_xlpm.v,_xlfn.XLOOKUP(G22,tblValutazioni[TipoValutazione],tblValutazioni[IN],""),IF(_xlpm.v="","",_xlpm.v))} -> 1 | R22: =IF(_xlfn.XLOOKUP($A22, tblRisposte[ItemKey], tblRisposte[Valore], "")="Insufficiente","X",0) -> 0 | S22: =IF((R22="X"),Q22,0) -> 0 | T22: {=_xlfn.LET(_xlpm.v,_xlfn.XLOOKUP(G22,tblValutazioni[TipoValutazione],tblValutazioni[NE],""),IF(_xlpm.v="","",_xlpm.v))} -> 0 | U22: =IF(_xlfn.XLOOKUP($A22, tblRisposte[ItemKey], tblRisposte[Valore], "")="Non eseguito","X",0) -> 0 | V22: =IF((U22="X"),T22,0) -> 0 | W22: =COUNTIF(I22,"x")+COUNTIF(L22,"x")+COUNTIF(O22,"x")+COUNTIF(R22,"x")+COUNTIF(U22,"x") -> 0 | X22: =IF(COUNTIF(I22:U22,"X")=1,"OK","errore") -> errore | Y22: =IF(E22="SEP",IF(I22="x",H22,IF(L22="X",K22,IF(O22="x",N22,IF(R22="X",Q22,IF(U22="X",T22,""))))),"")
